2021-11-07 19:23:30,042 INFO    MainThread:26828 [internal.py:wandb_internal():87] W&B internal server running at pid: 26828, started at: 2021-11-07 19:23:30.041026
2021-11-07 19:23:30,043 INFO    WriterThread:26828 [datastore.py:open_for_write():77] open: C:\Users\User\Desktop\yolov5-new-20211105T100344Z-001 - Copy\wandb\run-20211107_192328-2l4b4zkg\run-2l4b4zkg.wandb
2021-11-07 19:23:30,044 DEBUG   HandlerThread:26828 [handler.py:handle_request():130] handle_request: check_version
2021-11-07 19:23:30,045 DEBUG   SenderThread:26828 [sender.py:send():238] send: header
2021-11-07 19:23:30,045 DEBUG   SenderThread:26828 [sender.py:send_request():252] send_request: check_version
2021-11-07 19:23:30,064 DEBUG   SenderThread:26828 [sender.py:send():238] send: run
2021-11-07 19:23:30,071 INFO    SenderThread:26828 [sender.py:_maybe_setup_resume():505] checking resume status for None/train/2l4b4zkg
2021-11-07 19:23:33,515 ERROR   SenderThread:26828 [retry.py:__call__():126] Retry attempt failed:
Traceback (most recent call last):
  File "C:\Python39\lib\site-packages\urllib3\connection.py", line 174, in _new_conn
    conn = connection.create_connection(
  File "C:\Python39\lib\site-packages\urllib3\util\connection.py", line 73, in create_connection
    for res in socket.getaddrinfo(host, port, family, socket.SOCK_STREAM):
  File "C:\Python39\lib\socket.py", line 954, in getaddrinfo
    for res in _socket.getaddrinfo(host, port, family, type, proto, flags):
socket.gaierror: [Errno 11001] getaddrinfo failed

During handling of the above exception, another exception occurred:

Traceback (most recent call last):
  File "C:\Python39\lib\site-packages\urllib3\connectionpool.py", line 699, in urlopen
    httplib_response = self._make_request(
  File "C:\Python39\lib\site-packages\urllib3\connectionpool.py", line 382, in _make_request
    self._validate_conn(conn)
  File "C:\Python39\lib\site-packages\urllib3\connectionpool.py", line 1010, in _validate_conn
    conn.connect()
  File "C:\Python39\lib\site-packages\urllib3\connection.py", line 358, in connect
    conn = self._new_conn()
  File "C:\Python39\lib\site-packages\urllib3\connection.py", line 186, in _new_conn
    raise NewConnectionError(
urllib3.exceptions.NewConnectionError: <urllib3.connection.HTTPSConnection object at 0x0000019415E23550>: Failed to establish a new connection: [Errno 11001] getaddrinfo failed

During handling of the above exception, another exception occurred:

Traceback (most recent call last):
  File "C:\Users\User\AppData\Roaming\Python\Python39\site-packages\requests\adapters.py", line 439, in send
    resp = conn.urlopen(
  File "C:\Python39\lib\site-packages\urllib3\connectionpool.py", line 755, in urlopen
    retries = retries.increment(
  File "C:\Python39\lib\site-packages\urllib3\util\retry.py", line 574, in increment
    raise MaxRetryError(_pool, url, error or ResponseError(cause))
urllib3.exceptions.MaxRetryError: HTTPSConnectionPool(host='api.wandb.ai', port=443): Max retries exceeded with url: /graphql (Caused by NewConnectionError('<urllib3.connection.HTTPSConnection object at 0x0000019415E23550>: Failed to establish a new connection: [Errno 11001] getaddrinfo failed'))

During handling of the above exception, another exception occurred:

Traceback (most recent call last):
  File "C:\Python39\lib\site-packages\wandb\sdk\lib\retry.py", line 102, in __call__
    result = self._call_fn(*args, **kwargs)
  File "C:\Python39\lib\site-packages\wandb\sdk\internal\internal_api.py", line 141, in execute
    return self.client.execute(*args, **kwargs)
  File "C:\Python39\lib\site-packages\wandb\vendor\gql-0.2.0\gql\client.py", line 52, in execute
    result = self._get_result(document, *args, **kwargs)
  File "C:\Python39\lib\site-packages\wandb\vendor\gql-0.2.0\gql\client.py", line 60, in _get_result
    return self.transport.execute(document, *args, **kwargs)
  File "C:\Python39\lib\site-packages\wandb\vendor\gql-0.2.0\gql\transport\requests.py", line 38, in execute
    request = requests.post(self.url, **post_args)
  File "C:\Users\User\AppData\Roaming\Python\Python39\site-packages\requests\api.py", line 117, in post
    return request('post', url, data=data, json=json, **kwargs)
  File "C:\Users\User\AppData\Roaming\Python\Python39\site-packages\requests\api.py", line 61, in request
    return session.request(method=method, url=url, **kwargs)
  File "C:\Users\User\AppData\Roaming\Python\Python39\site-packages\requests\sessions.py", line 542, in request
    resp = self.send(prep, **send_kwargs)
  File "C:\Users\User\AppData\Roaming\Python\Python39\site-packages\requests\sessions.py", line 655, in send
    r = adapter.send(request, **kwargs)
  File "C:\Users\User\AppData\Roaming\Python\Python39\site-packages\requests\adapters.py", line 516, in send
    raise ConnectionError(e, request=request)
requests.exceptions.ConnectionError: HTTPSConnectionPool(host='api.wandb.ai', port=443): Max retries exceeded with url: /graphql (Caused by NewConnectionError('<urllib3.connection.HTTPSConnection object at 0x0000019415E23550>: Failed to establish a new connection: [Errno 11001] getaddrinfo failed'))
2021-11-07 19:24:00,078 DEBUG   HandlerThread:26828 [handler.py:handle_request():130] handle_request: shutdown
2021-11-07 19:24:00,078 INFO    HandlerThread:26828 [handler.py:finish():731] shutting down handler
2021-11-07 19:24:00,249 INFO    WriterThread:26828 [datastore.py:close():281] close: C:\Users\User\Desktop\yolov5-new-20211105T100344Z-001 - Copy\wandb\run-20211107_192328-2l4b4zkg\run-2l4b4zkg.wandb
